<robot name="robot_one"
  xmlns:xacro="http://www.ros.org/wiki/xacro">

  <!-- xacro macro definition -->
  <!-- Computing the inertial matrix for a box -->
  <xacro:macro name="Box_inertial_matrix" params="m l w h">
    <inertial>
      <mass value="${m}" />
      <inertia ixx="${m*(h*h + l*l)/12}" ixy = "0" ixz = "0" iyy="${m*(w*w + l*l)/12}" iyz= "0" izz="${m*(w*w + h*h)/12}" />
    </inertial>
  </xacro:macro>

  <!-- Mapping the coordinate relative to the link-frame from a cylindrical form to a cartesian one   -->
  <xacro:macro name="cylindrical2Cartesian" params="rou phi z">
    <origin rpy="0 ${pi/2} ${phi}" xyz="${rou*cos(phi)} ${rou*sin(phi)} ${z}"/>
  </xacro:macro>

  <!-- Mapping the pose relative to the link-frame from a cylindrical form to a cartesian one   -->
  <xacro:macro name="sensorCylindrical2Cartesian" params="rou phi z">
    <pose>${rou*cos(phi)} ${rou*sin(phi)} ${z} 0 ${pi/2} ${phi}</pose>
  </xacro:macro>

  <!-- Defining a new ToF sensor -->
  <xacro:macro name="ToF" params="index">
    <joint name="ToF${index}_Joint" type="fixed">
      <axis xyz="0 0 1" />
      <origin rpy="1.5708 0 0" xyz="0 -0.30175 -0.0655"/>
      <parent link="Joint6_Link"/>
      <child link="ToF${index}_Link"/>
    </joint>

    <link name="ToF${index}_Link">
      <collision>
        <xacro:cylindrical2Cartesian rou="0.043" phi="${radians(22.5*index)}" z="-0.1"/>
        <geometry>
          <box size="0.0028 0.0048 0.001"/>
        </geometry>
      </collision>
      <visual>
        <xacro:cylindrical2Cartesian rou="0.043" phi="${radians(22.5*index)}" z="-0.1"/>
        <geometry>
          <box size="0.0028 0.0048 0.001"/>
        </geometry>
      </visual>
      <xacro:Box_inertial_matrix m="1e-5" w="0.0028" l="0.0048" h="0.001"/>
    </link>

    <gazebo reference="ToF${index}_Link">
      <material>Gazebo/White</material>
    </gazebo>
    <gazebo reference="ToF${index}_Link">
      <sensor name="ToF${index}" type="sonar">
        <always_on>true</always_on>
        <xacro:sensorCylindrical2Cartesian rou="0.043" phi="${radians(22.5*index)}" z="-0.1"/>
        <update_rate>10</update_rate>
        <visualize>true</visualize>
        <sonar>
          <min>0.01</min>
          <max>0.6</max>
          <radius>0.1330167976</radius>
        </sonar>
        <plugin name="nps_gazebo_ros_sonar_plugin" filename="libnps_gazebo_ros_sonar_plugin.so">
          <topicName>ToF${index}</topicName>
          <frameName>ToF${index}_Link</frameName>
        </plugin>
      </sensor>
    </gazebo>
  </xacro:macro>

  <!-- Main body of urdf -->
  <link name="dummy">
  </link>

  <joint name="dummy_joint" type="fixed">
    <parent link="dummy"/>
    <child link="base_link"/>
  </joint>
  
  <link name="base_link">
    <inertial>
      <origin rpy="0 0 0" xyz="-0.00050672 -0.00050785 0.062888"/>
      <mass value="15.177"/>
      <inertia ixx="0.083295" ixy="0.0005776" ixz="-0.00028833" iyy="0.083294" iyz="-0.0002891" izz="0.11636"/>
    </inertial>
    <visual>
      <origin rpy="0 0 0" xyz="0 0 0"/>
      <geometry>
        <mesh filename="package://robot_gazebo/meshes/base_link.STL"/>
      </geometry>
      <material name="">
        <color rgba="0.89804 0.91765 0.92941 1"/>
      </material>
    </visual>
    <collision>
      <origin rpy="0 0 0" xyz="0 0 0"/>
      <geometry>
        <mesh filename="package://robot_gazebo/meshes/base_link.STL"/>
      </geometry>
    </collision>
  </link>

  <link name="Joint1_Link">
    <inertial>
      <origin rpy="0 0 0" xyz="3.815E-05 0.00060867 0.14101"/>
      <mass value="3.2589"/>
      <inertia ixx="0.015737" ixy="-1.9942E-06" ixz="-6.3989E-06" iyy="0.01209" iyz="-0.0020351" izz="0.010023"/>
    </inertial>
    <visual>
      <origin rpy="0 0 0" xyz="0 0 0"/>
      <geometry>
        <mesh filename="package://robot_gazebo/meshes/Joint1_Link.STL"/>
      </geometry>
      <material name="">
        <color rgba="0.89804 0.91765 0.92941 1"/>
      </material>
    </visual>
    <collision>
      <origin rpy="0 0 0" xyz="0 0 0"/>
      <geometry>
        <mesh filename="package://robot_gazebo/meshes/Joint1_Link.STL"/>
      </geometry>
    </collision>
  </link>

  <joint name="Joint1" type="revolute">
    <origin rpy="0 0 0" xyz="0 0 0.146"/>
    <parent link="base_link"/>
    <child link="Joint1_Link"/>
    <axis xyz="0 0 1"/>
    <limit effort="100" lower="-3" upper="3" velocity="100"/>
  </joint>

  <link name="Joint2_Link">
    <inertial>
      <origin rpy="0 0 0" xyz="-2.4813E-06 -0.14619 -0.05412"/>
      <mass value="1.4714"/>
      <inertia ixx="0.010571" ixy="5.4064E-08" ixz="-3.4511E-07" iyy="0.0045856" iyz="-0.0033059" izz="0.0094805"/>
    </inertial>
    <visual>
      <geometry>
        <mesh filename="package://robot_gazebo/meshes/Joint2_Link.STL"/>
      </geometry>
      <material name="">
        <color rgba="0.89804 0.91765 0.92941 1"/>
      </material>
    </visual>
    <collision>
      <geometry>
        <mesh filename="package://robot_gazebo/meshes/Joint2_Link.STL"/>
      </geometry>
    </collision>
  </link>

  <joint name="Joint2" type="continuous">
    <origin rpy="-1.5708 0 0" xyz="0 0.084 0.157"/>
    <parent link="Joint1_Link"/>
    <child link="Joint2_Link"/>
    <axis xyz="0 0 1"/>
    <limit effort="100" lower="-2" upper="2" velocity="100"/>
  </joint>

  <link name="Joint3_Link">
    <inertial>
      <origin rpy="0 0 0" xyz="-2.4607E-06 -0.019343 0.11276"/>
      <mass value="1.4332"/>
      <inertia ixx="0.0069817" ixy="-1.4824E-07" ixz="3.5058E-07" iyy="0.005899" iyz="-0.00084107" izz="0.0034704"/>
    </inertial>
    <visual>
      <geometry>
        <mesh filename="package://robot_gazebo/meshes/Joint3_Link.STL"/>
      </geometry>
      <material name="">
        <color rgba="0.89804 0.91765 0.92941 1"/>
      </material>
    </visual>
    <collision>
      <geometry>
        <mesh filename="package://robot_gazebo/meshes/Joint3_Link.STL"/>
      </geometry>
    </collision>
  </link>

  <joint name="Joint3" type="continuous">
    <origin rpy="1.5708 0 0" xyz="0 -0.258 -0.084"/>
    <parent link="Joint2_Link"/>
    <child link="Joint3_Link"/>
    <axis xyz="0 0 1"/>
    <limit effort="100" lower="-3" upper="3" velocity="100"/>
  </joint>

  <link name="Joint4_Link">
    <inertial>
      <origin rpy="0 0 0" xyz="2.1939E-05 -0.1389 -0.038332"/>
      <mass value="1.1839"/>
      <inertia ixx="0.0078173" ixy="2.3828E-06" ixz="4.1091E-07" iyy="0.0026824" iyz="-0.002166" izz="0.007437"/>
    </inertial>
    <visual>
      <origin rpy="0 0 0" xyz="0 0 0"/>
      <geometry>
        <mesh filename="package://robot_gazebo/meshes/Joint4_Link.STL"/>
      </geometry>
      <material name="">
        <color rgba="0.89804 0.91765 0.92941 1"/>
      </material>
    </visual>
    <collision>
      <origin rpy="0 0 0" xyz="0 0 0"/>
      <geometry>
        <mesh filename="package://robot_gazebo/meshes/Joint4_Link.STL"/>
      </geometry>
    </collision>
  </link>

  <joint name="Joint4" type="continuous">
    <origin rpy="-1.5708 0 0" xyz="0 0.065 0.142"/>
    <parent link="Joint3_Link"/>
    <child link="Joint4_Link"/>
    <axis xyz="0 0 1"/>
    <limit effort="100" lower="-3" upper="1" velocity="100"/>
  </joint>

  <link name="Joint5_Link">
    <inertial>
      <origin rpy="0 0 0" xyz="2.2915E-05 -0.013559 0.11664"/>
      <mass value="1.1389"/>
      <inertia ixx="0.0054051" ixy="-1.5393E-06" ixz="-5.7318E-07" iyy="0.0047158" iyz="-0.00065943" izz="0.0021965"/>
    </inertial>
    <visual>
      <origin rpy="0 0 0" xyz="0 0 0"/>
      <geometry>
        <mesh filename="package://robot_gazebo/meshes/Joint5_Link.STL"/>
      </geometry>
      <material name="">
        <color rgba="0.89804 0.91765 0.92941 1"/>
      </material>
    </visual>
    <collision>
      <origin rpy="0 0 0" xyz="0 0 0"/>
      <geometry>
        <mesh filename="package://robot_gazebo/meshes/Joint5_Link.STL"/>
      </geometry>
    </collision>
  </link>

  <joint name="Joint5" type="continuous">
    <origin rpy="1.5708 0 0" xyz="0 -0.25025 -0.065"/>
    <parent link="Joint4_Link"/>
    <child link="Joint5_Link"/>
    <axis xyz="0 0 1"/>
    <limit effort="12" lower="-3" upper="3" velocity="3"/>
  </joint>

  <link name="Joint6_Link">
    <inertial>
      <origin rpy="0 0 0" xyz="2.1743E-05 -0.13692 -0.038492"/>
      <mass value="1.1946"/>
      <inertia ixx="0.0082077" ixy="2.4344E-06" ixz="4.1972E-07" iyy="0.0026929" iyz="-0.0022555" izz="0.0078073"/>
    </inertial>
    <visual>
      <geometry>
        <mesh filename="package://robot_gazebo/meshes/Joint6_Link.STL"/>
      </geometry>
      <material name="">
        <color rgba="0.89804 0.91765 0.92941 1"/>
      </material>
    </visual>
    <collision>
      <geometry>
        <mesh filename="package://robot_gazebo/meshes/Joint6_Link.STL"/>
      </geometry>
    </collision>
  </link>

  <joint name="Joint6" type="continuous">
    <origin rpy="-1.5708 0 0" xyz="0 0.0655 0.14975"/>
    <parent link="Joint5_Link"/>
    <child link="Joint6_Link"/>
    <axis xyz="0 0 1"/>
    <limit effort="12" lower="-1" upper="4" velocity="3"/>
  </joint>

  <link name="Joint7_Link">
    <inertial>
      <origin rpy="0 0 0" xyz="8.2379E-14 2.8922E-14 -0.038682"/>
      <mass value="0.2104"/>
      <inertia ixx="0.00027857" ixy="-1.5757E-20" ixz="-2.2111E-20" iyy="3.527E-05" iyz="8.0866E-19" izz="0.00027439"/>
    </inertial>
    <visual>
      <geometry>
        <mesh filename="package://robot_gazebo/meshes/Joint7_Link.STL"/>
      </geometry>
      <material name="">
        <color rgba="0.89804 0.91765 0.92941 1"/>
      </material>
    </visual>
    <collision>
      <geometry>
        <mesh filename="package://robot_gazebo/meshes/Joint7_Link.STL"/>
      </geometry>
    </collision>
  </link>

  <joint name="Joint7" type="continuous">
    <origin rpy="1.5708 0 0" xyz="0 -0.30175 -0.0655"/>
    <parent link="Joint6_Link"/>
    <child link="Joint7_Link"/>
    <axis xyz="0 0 1"/>
    <limit effort="12" lower="-1" upper="4" velocity="3"/>
  </joint>

  <!-- Implementing the xacro macro -->
  <xacro:ToF index="1"/>
  <xacro:ToF index="2"/>
  <xacro:ToF index="3"/>
  <xacro:ToF index="4"/>
  <xacro:ToF index="5"/>
  <xacro:ToF index="6"/>
  <xacro:ToF index="7"/>
  <xacro:ToF index="8"/>
  <xacro:ToF index="9"/>
  <xacro:ToF index="10"/>
  <xacro:ToF index="11"/>
  <xacro:ToF index="12"/>
  <xacro:ToF index="13"/>
  <xacro:ToF index="14"/>
  <xacro:ToF index="15"/>
  <xacro:ToF index="16"/>

  <!-- gazebo -->
  <gazebo reference="base_link">
    <material>Gazebo/Black</material>
  </gazebo>
  <gazebo reference="Joint1_Link">
    <material>Gazebo/Black</material>
  </gazebo>
  <gazebo reference="Joint2_Link">
    <material>Gazebo/Black</material>
  </gazebo>
  <gazebo reference="Joint3_Link">
    <material>Gazebo/Black</material>
  </gazebo>
  <gazebo reference="Joint4_Link">
    <material>Gazebo/Black</material>
  </gazebo>
  <gazebo reference="Joint5_Link">
    <material>Gazebo/Black</material>
  </gazebo>
  <gazebo reference="Joint6_Link">
    <material>Gazebo/Black</material>
  </gazebo>
  <gazebo reference="Joint7_Link">
    <material>Gazebo/Black</material>
  </gazebo>
  <gazebo>
    <plugin filename="libgazebo_ros_control.so" name="gazebo_ros_control"/>
    <robotNamespace>/robot_one</robotNamespace>
  </gazebo>
  <gazebo reference="Joint1">
    <!-- Needed for ODE to output external wrenches on joints -->
    <provideFeedback>true</provideFeedback>
  </gazebo>
  <transmission name="Joint1_transmission">
    <type>transmission_interface/SimpleTransmission</type>
    <joint name="Joint1">
      <hardwareInterface>hardware_interface/PositionJointInterface</hardwareInterface>
    </joint>
    <actuator name="Joint1_motor">
      <hardwareInterface>hardware_interface/PositionJointInterface</hardwareInterface>
      <mechanicalReduction>1</mechanicalReduction>
    </actuator>
  </transmission>
  <gazebo reference="Joint2">
    <!-- Needed for ODE to output external wrenches on joints -->
    <provideFeedback>true</provideFeedback>
  </gazebo>
  <transmission name="Joint2_transmission">
    <type>transmission_interface/SimpleTransmission</type>
    <joint name="Joint2">
      <hardwareInterface>hardware_interface/PositionJointInterface</hardwareInterface>
    </joint>
    <actuator name="Joint2_motor">
      <hardwareInterface>hardware_interface/PositionJointInterface</hardwareInterface>
      <mechanicalReduction>1</mechanicalReduction>
    </actuator>
  </transmission>
  <gazebo reference="Joint3">
    <!-- Needed for ODE to output external wrenches on joints -->
    <provideFeedback>true</provideFeedback>
  </gazebo>
  <transmission name="Joint3_transmission">
    <type>transmission_interface/SimpleTransmission</type>
    <joint name="Joint3">
      <hardwareInterface>hardware_interface/PositionJointInterface</hardwareInterface>
    </joint>
    <actuator name="Joint3_motor">
      <hardwareInterface>hardware_interface/PositionJointInterface</hardwareInterface>
      <mechanicalReduction>1</mechanicalReduction>
    </actuator>
  </transmission>
  <gazebo reference="Joint4">
    <!-- Needed for ODE to output external wrenches on joints -->
    <provideFeedback>true</provideFeedback>
  </gazebo>
  <transmission name="Joint4_transmission">
    <type>transmission_interface/SimpleTransmission</type>
    <joint name="Joint4">
      <hardwareInterface>hardware_interface/PositionJointInterface</hardwareInterface>
    </joint>
    <actuator name="Joint4_motor">
      <hardwareInterface>hardware_interface/PositionJointInterface</hardwareInterface>
      <mechanicalReduction>1</mechanicalReduction>
    </actuator>
  </transmission>
  <gazebo reference="Joint5">
    <!-- Needed for ODE to output external wrenches on joints -->
    <provideFeedback>true</provideFeedback>
  </gazebo>
  <transmission name="Joint5_transmission">
    <type>transmission_interface/SimpleTransmission</type>
    <joint name="Joint5">
      <hardwareInterface>hardware_interface/PositionJointInterface</hardwareInterface>
    </joint>
    <actuator name="Joint5_motor">
      <hardwareInterface>hardware_interface/PositionJointInterface</hardwareInterface>
      <mechanicalReduction>1</mechanicalReduction>
    </actuator>
  </transmission>
  <gazebo reference="Joint6">
    <!-- Needed for ODE to output external wrenches on joints -->
    <provideFeedback>true</provideFeedback>
  </gazebo>
  <transmission name="Joint6_transmission">
    <type>transmission_interface/SimpleTransmission</type>
    <joint name="Joint6">
      <hardwareInterface>hardware_interface/PositionJointInterface</hardwareInterface>
    </joint>
    <actuator name="Joint6_motor">
      <hardwareInterface>hardware_interface/PositionJointInterface</hardwareInterface>
      <mechanicalReduction>1</mechanicalReduction>
    </actuator>
  </transmission>
  <gazebo reference="Joint7">
    <!-- Needed for ODE to output external wrenches on joints -->
    <provideFeedback>true</provideFeedback>
  </gazebo>
  <transmission name="Joint7_transmission">
    <type>transmission_interface/SimpleTransmission</type>
    <joint name="Joint7">
      <hardwareInterface>hardware_interface/PositionJointInterface</hardwareInterface>
    </joint>
    <actuator name="Joint7_motor">
      <hardwareInterface>hardware_interface/PositionJointInterface</hardwareInterface>
      <mechanicalReduction>1</mechanicalReduction>
    </actuator>
  </transmission>
</robot>